┌────────────────────────────────────────────────────────────────────────────────────┐
│                             Invision Archive Tools v1.0.0                          │
│                             Linux 6.8.0-64-generic amd64                           │
│                                                                                    │
│                 Copyright (C) Mark Fisher, 2025. All rights reserved.              │
│                      See Terms of Service for more information.                    │
└────────────────────────────────────────────────────────────────────────────────────┘
Vendor: JetBrains s.r.o.
  |_ https://openjdk.org/
JRE: OpenJDK Runtime Environment
  |_ 21.0.6+-13355223-b631.42
Library Path: /usr/java/packages/lib:/usr/lib64:/lib64:/lib:/usr/lib
--------------------------------------------------------------------------------------
[main] INFO 14:19:13 Core - Started executor service [5ms]
[main] INFO 14:19:13 ServerExtractor - Server installation is up-to-date.
[main] INFO 14:19:14 Core - Session began on 07/30/2025
[PyServer] [MainThread] INFO - IAT server started successfully.
[PyServer] [MainThread] INFO - Debug mode is enabled.
[PyServer] [MainThread] INFO - Waiting for client commands...
Jul 30, 2025 2:19:15 PM com.sun.javafx.application.PlatformImpl startup
WARNING: Unsupported JavaFX configuration: classes were loaded from 'unnamed module @5223e5ee'
[main] INFO 14:19:15 Core - Initialized JavaFX [375ms]
[PyServer] [MainThread] INFO - Root URL: https://catholicharbor.com
[stdout] DEBUG 14:19:16 Server - stdout << {"worker_id": null, "shared_action": "UUID_AVAILABLE", "data": {"uuid": "ed2ca975-1c9d-48b4-b853-e874248a1b9b"}}
[PyServer] [ed2ca975-1c9d-48b4-b853-e874248a1b9b] INFO - Starting chromedriver...
[AWT-EventQueue-0] DEBUG 14:19:16 Server - stdin >> {"data":{"worker_type":"TOPIC_WORKER","ic":{"root_url":"https://catholicharbor.com","version":4}},"shared_action":"DISPATCH_WORKER","worker_id":null}
[stdout] DEBUG 14:19:16 Server - stdout << {"worker_id": "ed2ca975-1c9d-48b4-b853-e874248a1b9b", "shared_action": "STATE_CHANGED", "data": {"state": {"note": "Initializing... Please wait...", "hint": "", "button_configs": null, "indeterminate": true}}}
[AWT-EventQueue-0] DEBUG 14:19:21 Server - stdin >> {"data":{},"shared_action":"TERMINATE_WORKER","worker_id":"ed2ca975-1c9d-48b4-b853-e874248a1b9b"}
[PyServer] [MainThread] WARNING - Error shutting down worker: Traceback (most recent call last):
[PyServer]   File "src/main.py", line 101, in process_client_cmd
[PyServer]   File "src/worker/ic_worker.py", line 152, in shutdown
[PyServer] AttributeError: 'TopicWorkerV4' object has no attribute 'driver'
[PyServer] 
[PyServer] [MainThread] INFO - Root URL: https://catholicharbor.com[AWT-EventQueue-0] DEBUG 14:19:24 Server - stdin >> {"data":{"worker_type":"MESSENGER_WORKER","ic":{"root_url":"https://catholicharbor.com","version":4}},"shared_action":"DISPATCH_WORKER","worker_id":null}

[stdout] DEBUG 14:19:24 Server - stdout << {"worker_id": null, "shared_action": "UUID_AVAILABLE", "data": {"uuid": "1d67ed2a-5b2c-4494-9466-6dc90aaa7758"}}
[PyServer] [1d67ed2a-5b2c-4494-9466-6dc90aaa7758] INFO - Starting chromedriver...
[stdout] DEBUG 14:19:24 Server - stdout << {"worker_id": "1d67ed2a-5b2c-4494-9466-6dc90aaa7758", "shared_action": "STATE_CHANGED", "data": {"state": {"note": "Initializing... Please wait...", "hint": "", "button_configs": null, "indeterminate": true}}}
[stdout] DEBUG 14:19:45 Server - stdout << {"worker_id": "ed2ca975-1c9d-48b4-b853-e874248a1b9b", "shared_action": "CHROMEDRIVER_ERROR", "data": {"stacktrace": "Traceback (most recent call last):\n  File \"urllib3/connectionpool.py\", line 787, in urlopen\n  File \"urllib3/connectionpool.py\", line 534, in _make_request\n  File \"urllib3/connection.py\", line 565, in getresponse\n  File \"http/client.py\", line 1428, in getresponse\n  File \"http/client.py\", line 331, in begin\n  File \"http/client.py\", line 300, in _read_status\nhttp.client.RemoteDisconnected: Remote end closed connection without response\n\nDuring handling of the above exception, another exception occurred:\n\nTraceback (most recent call last):\n  File \"src/worker/ic_worker.py\", line 76, in run\n  File \"src/worker/ic_worker.py\", line 179, in create_chromedriver\n  File \"src/worker/ic_chromedriver.py\", line 29, in __init__\n  File \"undetected_chromedriver/__init__.py\", line 466, in __init__\n  File \"selenium/webdriver/chrome/webdriver.py\", line 47, in __init__\n  File \"selenium/webdriver/chromium/webdriver.py\", line 69, in __init__\n  File \"selenium/webdriver/remote/webdriver.py\", line 261, in __init__\n  File \"undetected_chromedriver/__init__.py\", line 724, in start_session\n  File \"selenium/webdriver/remote/webdriver.py\", line 362, in start_session\n  File \"selenium/webdriver/remote/webdriver.py\", line 451, in execute\n  File \"selenium/webdriver/remote/remote_connection.py\", line 404, in execute\n  File \"selenium/webdriver/remote/remote_connection.py\", line 428, in _request\n  File \"urllib3/_request_methods.py\", line 143, in request\n  File \"urllib3/_request_methods.py\", line 278, in request_encode_body\n  File \"urllib3/poolmanager.py\", line 459, in urlopen\n  File \"urllib3/connectionpool.py\", line 841, in urlopen\n  File \"urllib3/util/retry.py\", line 474, in increment\n  File \"urllib3/util/util.py\", line 38, in reraise\n  File \"urllib3/connectionpool.py\", line 787, in urlopen\n  File \"urllib3/connectionpool.py\", line 534, in _make_request\n  File \"urllib3/connection.py\", line 565, in getresponse\n  File \"http/client.py\", line 1428, in getresponse\n  File \"http/client.py\", line 331, in begin\n  File \"http/client.py\", line 300, in _read_status\nurllib3.exceptions.ProtocolError: ('Connection aborted.', RemoteDisconnected('Remote end closed connection without response'))\n"}}
[PyServer] [ed2ca975-1c9d-48b4-b853-e874248a1b9b] FATAL - Failed to start chromedriver: Traceback (most recent call last):
[PyServer]   File "urllib3/connectionpool.py", line 787, in urlopen
[PyServer]   File "urllib3/connectionpool.py", line 534, in _make_request
[PyServer]   File "urllib3/connection.py", line 565, in getresponse
[PyServer]   File "http/client.py", line 1428, in getresponse
[PyServer]   File "http/client.py", line 331, in begin
[PyServer]   File "http/client.py", line 300, in _read_status
[PyServer] http.client.RemoteDisconnected: Remote end closed connection without response
[PyServer] 
[PyServer] During handling of the above exception, another exception occurred:
[PyServer] 
[PyServer] Traceback (most recent call last):
[PyServer]   File "src/worker/ic_worker.py", line 76, in run
[PyServer]   File "src/worker/ic_worker.py", line 179, in create_chromedriver
[PyServer]   File "src/worker/ic_chromedriver.py", line 29, in __init__
[PyServer]   File "undetected_chromedriver/__init__.py", line 466, in __init__
[PyServer]   File "selenium/webdriver/chrome/webdriver.py", line 47, in __init__
[PyServer]   File "selenium/webdriver/chromium/webdriver.py", line 69, in __init__
[PyServer]   File "selenium/webdriver/remote/webdriver.py", line 261, in __init__
[PyServer]   File "undetected_chromedriver/__init__.py", line 724, in start_session
[PyServer]   File "selenium/webdriver/remote/webdriver.py", line 362, in start_session
[PyServer]   File "selenium/webdriver/remote/webdriver.py", line 451, in execute
[PyServer]   File "selenium/webdriver/remote/remote_connection.py", line 404, in execute
[PyServer]   File "selenium/webdriver/remote/remote_connection.py", line 428, in _request
[PyServer]   File "urllib3/_request_methods.py", line 143, in request
[PyServer]   File "urllib3/_request_methods.py", line 278, in request_encode_body
[PyServer]   File "urllib3/poolmanager.py", line 459, in urlopen
[PyServer]   File "urllib3/connectionpool.py", line 841, in urlopen
[PyServer]   File "urllib3/util/retry.py", line 474, in increment
[PyServer]   File "urllib3/util/util.py", line 38, in reraise
[PyServer]   File "urllib3/connectionpool.py", line 787, in urlopen
[PyServer]   File "urllib3/connectionpool.py", line 534, in _make_request
[PyServer]   File "urllib3/connection.py", line 565, in getresponse
[PyServer]   File "http/client.py", line 1428, in getresponse
[PyServer]   File "http/client.py", line 331, in begin
[PyServer]   File "http/client.py", line 300, in _read_status
[PyServer] urllib3.exceptions.ProtocolError: ('Connection aborted.', RemoteDisconnected('Remote end closed connection without response'))
[PyServer] 
[PyServer] [1d67ed2a-5b2c-4494-9466-6dc90aaa7758] INFO - current_url => https://catholicharbor.com/login
[stdout] DEBUG 14:19:49 Server - stdout << {"worker_id": "1d67ed2a-5b2c-4494-9466-6dc90aaa7758", "shared_action": "STATE_CHANGED", "data": {"state": {"note": "Validating session...", "hint": "", "button_configs": null, "indeterminate": true}}}
[PyServer] [1d67ed2a-5b2c-4494-9466-6dc90aaa7758] INFO - Session valid, proceeding...
[PyServer] [1d67ed2a-5b2c-4494-9466-6dc90aaa7758] INFO - current_url => https://catholicharbor.com/messenger
[stdout] DEBUG 14:19:57 Server - stdout << {"worker_id": "1d67ed2a-5b2c-4494-9466-6dc90aaa7758", "shared_action": "STATE_CHANGED", "data": {"state": {"note": "Select a messenger to archive.", "hint": "Click on a messenger in the browser and press 'Next'", "button_configs": [{"text": "Next", "shared_action": "NONE", "client_object": true}], "indeterminate": true}}}
[AWT-EventQueue-0] DEBUG 14:20:01 Server - stdin >> {"data":{"client_object":true},"shared_action":"STATE_INPUT","worker_id":"1d67ed2a-5b2c-4494-9466-6dc90aaa7758"}[PyServer] [MainThread] WARNING - Attempted to access non-existent worker (uuid: 1d67ed2a-5b2c-4494-9466-6dc90aaa7758)

[AWT-EventQueue-0] DEBUG 14:20:02 Server - stdin >> {"data":{"client_object":true},"shared_action":"STATE_INPUT","worker_id":"1d67ed2a-5b2c-4494-9466-6dc90aaa7758"}[PyServer] [MainThread] WARNING - Attempted to access non-existent worker (uuid: 1d67ed2a-5b2c-4494-9466-6dc90aaa7758)

[AWT-EventQueue-0] DEBUG 14:20:04 Server - stdin >> {"data":{"client_object":true},"shared_action":"STATE_INPUT","worker_id":"1d67ed2a-5b2c-4494-9466-6dc90aaa7758"}[PyServer] [MainThread] WARNING - Attempted to access non-existent worker (uuid: 1d67ed2a-5b2c-4494-9466-6dc90aaa7758)

[AWT-EventQueue-0] DEBUG 14:20:07 Server - stdin >> {"data":{"client_object":true},"shared_action":"STATE_INPUT","worker_id":"1d67ed2a-5b2c-4494-9466-6dc90aaa7758"}[PyServer] [MainThread] WARNING - Attempted to access non-existent worker (uuid: 1d67ed2a-5b2c-4494-9466-6dc90aaa7758)

[AWT-EventQueue-0] DEBUG 14:20:11 Server - stdin >> {"data":{"client_object":true},"shared_action":"STATE_INPUT","worker_id":"1d67ed2a-5b2c-4494-9466-6dc90aaa7758"}[PyServer] [MainThread] WARNING - Attempted to access non-existent worker (uuid: 1d67ed2a-5b2c-4494-9466-6dc90aaa7758)

[AWT-EventQueue-0] DEBUG 14:20:11 Server - stdin >> {"data":{"client_object":true},"shared_action":"STATE_INPUT","worker_id":"1d67ed2a-5b2c-4494-9466-6dc90aaa7758"}[PyServer] [MainThread] WARNING - Attempted to access non-existent worker (uuid: 1d67ed2a-5b2c-4494-9466-6dc90aaa7758)

